Workbook

Sheet BOQ
A1: BILL OF QUANTITIES — FIRE ALARM & VOICE EVACUATION SYSTEM
A2: Drawing ICC-DLRC-SIG2-SD-MEP/FA-109 Rev 01 (15.09.2026) — Level 02 to 10 & 12 to 16 (typical floor × 14)
A3: Quantities counted from the DXF. Rate and Amount columns are blank for the estimator. See 'Assumptions & Notes' for basis and open items.
A5: Item | B5: Description | C5: Model / Type | D5: Mounting height | E5: Unit | F5: Qty per typical floor | G5: No. of floors | H5: Total qty | I5: Rate (AED) | J5: Amount (AED) | K5: Remarks
A6: A. AUTOMATIC DETECTION DEVICES
A7: A.1 | B7: Intelligent photoelectric smoke detector complete with standard mounting base | C7: SIGA-OSD-FCN + SIGA-SB | D7: Ceiling mounted | E7: Nos | F7: 32 | G7: ='Assumptions & Notes'!$B$10 -> 14 | H7: =F7*G7 -> 448 | J7: =IF(N(I7)=0,"",H7*I7) | K7: Typical floor coverage. 36 symbols on plan less the 4 noted 'L6 & L12 only' below.
A8: A.2 | B8: Intelligent photoelectric smoke detector with standard base — additional units at Level 06 & 12 only | C8: SIGA-OSD-FCN + SIGA-SB | D8: Ceiling mounted | E8: Nos | F8: 4 | G8: ='Assumptions & Notes'!$B$12 -> 2 | H8: =F8*G8 -> 8 | J8: =IF(N(I8)=0,"",H8*I8) | K8: Drawing note: 'SD LOCATED ONLY IN LEVEL-6 & 12'.
A9: A.3 | B9: Intelligent photoelectric smoke detector complete with isolator base | C9: SIGA-OSD-FCN + SIGA-IB | D9: Ceiling mounted | E9: Nos | F9: 5 | G9: ='Assumptions & Notes'!$B$10 -> 14 | H9: =F9*G9 -> 70 | J9: =IF(N(I9)=0,"",H9*I9) | K9: Loop isolation per general note 4.
A10: A.4 | B10: Intelligent photoelectric smoke detector complete with sounder base | C10: SIGA-OSD-FCN + SIGA-LPS | D10: Ceiling mounted | E10: Nos | F10: 31 | G10: ='Assumptions & Notes'!$B$10 -> 14 | H10: =F10*G10 -> 434 | J10: =IF(N(I10)=0,"",H10*I10) | K10: Apartment sounder coverage; fed by the 24 V DC circuit.
A11: A.5 | B11: Intelligent multi-sensor detector (optical + heat) with standard base | C11: SIGA-OSHD-FCN + SIGA-SB | D11: Ceiling mounted | E11: Nos | F11: 26 | G11: ='Assumptions & Notes'!$B$10 -> 14 | H11: =F11*G11 -> 364 | J11: =IF(N(I11)=0,"",H11*I11) | K11: Kitchens / high-nuisance areas.
A12: A.6 | B12: Intelligent rate-of-rise heat detector complete with isolator base | C12: SIGA-HRD-FCN + SIGA-IB | D12: Ceiling mounted | E12: Nos | F12: 1 | G12: ='Assumptions & Notes'!$B$10 -> 14 | H12: =F12*G12 -> 14 | J12: =IF(N(I12)=0,"",H12*I12)
A13: B. MANUAL CALL POINTS, MODULES & INTERFACE DEVICES
A14: B.1 | B14: Addressable manual call point (break glass), surface type | C14: SIGA-278 | D14: 1200 mm from FFL | E14: Nos | F14: 3 | G14: ='Assumptions & Notes'!$B$10 -> 14 | H14: =F14*G14 -> 42 | J14: =IF(N(I14)=0,"",H14*I14) | K14: Mounts on 3"×3" G.I. back box — see item D.3.
A15: B.2 | B15: Addressable control relay module | C15: SIGA-CR | D15: As per site condition | E15: Nos | F15: 4 | G15: ='Assumptions & Notes'!$B$10 -> 14 | H15: =F15*G15 -> 56 | J15: =IF(N(I15)=0,"",H15*I15) | K15: Interface to MSFD / smoke control / sliding doors / ZCV.
A16: B.3 | B16: Addressable control relay module — even levels only | C16: SIGA-CR | D16: As per site condition | E16: Nos | F16: 2 | G16: ='Assumptions & Notes'!$B$11 -> 8 | H16: =F16*G16 -> 16 | J16: =IF(N(I16)=0,"",H16*I16) | K16: Drawing note: 'CR LOCATED ONLY IN LEVEL-02,04,06,08,10,12,14,16 ONLY'.
A17: B.4 | B17: Addressable dual input monitor module | C17: SIGA-CT2 | D17: As per site condition | E17: Nos | F17: 1 | G17: ='Assumptions & Notes'!$B$10 -> 14 | H17: =F17*G17 -> 14 | J17: =IF(N(I17)=0,"",H17*I17) | K17: 2 loop addresses.
A18: B.5 | B18: Addressable dual input riser module | C18: SIGA-CC2A | D18: As per site condition | E18: Nos | F18: 1 | G18: ='Assumptions & Notes'!$B$10 -> 14 | H18: =F18*G18 -> 14 | J18: =IF(N(I18)=0,"",H18*I18) | K18: Speaker circuit riser — returns to CC2A at telecom room.
A19: B.6 | B19: End-of-line resistor | C19: As per manufacturer | D19: — | E19: Nos | F19: 1 | G19: ='Assumptions & Notes'!$B$10 -> 14 | H19: =F19*G19 -> 14 | J19: =IF(N(I19)=0,"",H19*I19)
A20: B.7 | B20: Fire telephone jack, flush type | C20: 6830-3 | D20: 1200 mm from FFL | E20: Nos | F20: 3 | G20: ='Assumptions & Notes'!$B$10 -> 14 | H20: =F20*G20 -> 42 | J20: =IF(N(I20)=0,"",H20*I20) | K20: Mounts on 2"×4" G.I. concealed back box — see item D.4.
A21: C. VOICE EVACUATION & AUDIBLE DEVICES
A22: C.1 | B22: Ceiling mounted fire alarm speaker complete with fire dome | C22: EST-S186C | D22: Ceiling mounted | E22: Nos | F22: 13 | G22: ='Assumptions & Notes'!$B$10 -> 14 | H22: =F22*G22 -> 182 | J22: =IF(N(I22)=0,"",H22*I22) | K22: Speaker circuit CK4, addresses SP1–SP13.
A23: C.2 | B23: Voice evacuation amplifier | C23: APS6A/230 | D23: 1800 mm from FFL (top of panel) | E23: Nos | F23: 1 | G23: ='Assumptions & Notes'!$B$13 -> 3 | H23: =F23*G23 -> 3 | J23: =IF(N(I23)=0,"",H23*I23) | K23: Drawing note: 'AMPLIFIERS LOCATED ONLY IN LEVEL-03/09/15'.
A24: D. PANELS, POWER SUPPLY, CABLES & ACCESSORIES
A25: D.1 | B25: Sub fire alarm control panel | C25: EST4 | D25: 1800 mm from FFL (top of panel) | E25: Nos | F25: 1 | G25: ='Assumptions & Notes'!$B$14 -> 1 | H25: =F25*G25 -> 1 | J25: =IF(N(I25)=0,"",H25*I25) | K25: Drawing note: 'SUB FIRE ALARM CONTROL PANEL LOCATED AT L10 ONLY'.
A26: D.2 | B26: Booster power supply | C26: BPS10A/230 | D26: 1800 mm from FFL (top of panel) | E26: Nos | F26: 1 | G26: ='Assumptions & Notes'!$B$15 -> 1 | H26: =F26*G26 -> 1 | J26: =IF(N(I26)=0,"",H26*I26) | K26: Drawing note: 'BOOSTER POWER SUPPLY LOCATED ONLY IN LEVEL-09'.
A27: D.3 | B27: Detection loop cable, 2C × 1.5 mm² fire rated | C27: 2C×1.5 mm² FR | D27: In 25 mm Ø PVC conduit | E27: Mtr | F27: 654 | G27: ='Assumptions & Notes'!$B$10 -> 14 | H27: =ROUND(F27*G27*(1+'Assumptions & Notes'!$B$16),0) -> 10072 | J27: =IF(N(I27)=0,"",H27*I27) | K27: Measured route length on layer FA-LOOP CABLE. Loop 3 and Loop 4 pass this floor.
A28: D.4 | B28: 24 V DC power cable to sounder bases, 2C × 2.5 mm² fire rated | C28: 2C×2.5 mm² FR | D28: In 25 mm Ø PVC conduit | E28: Mtr | F28: 358 | G28: ='Assumptions & Notes'!$B$10 -> 14 | H28: =ROUND(F28*G28*(1+'Assumptions & Notes'!$B$16),0) -> 5513 | J28: =IF(N(I28)=0,"",H28*I28) | K28: Measured route length on layer FA-24V DC CIRCUIT.
A29: D.5 | B29: Voice evacuation speaker circuit cable, 2C × 2.5 mm² fire rated | C29: 2C×2.5 mm² FR | D29: In 25 mm Ø PVC conduit | E29: Mtr | F29: 157 | G29: ='Assumptions & Notes'!$B$10 -> 14 | H29: =ROUND(F29*G29*(1+'Assumptions & Notes'!$B$16),0) -> 2418 | J29: =IF(N(I29)=0,"",H29*I29) | K29: Measured route length on layer VE-SPEAKER CIRCUIT.
A30: D.6 | B30: Fire telephone cable, 2C × 1.5 mm² fire rated | C30: 2C×1.5 mm² FR | D30: In 25 mm Ø PVC conduit | E30: Mtr | F30: TBA | G30: — | H30: TBA | K30: NOT ROUTED ON THIS DRAWING — quantity to be taken from the riser / schematic.
A31: D.7 | B31: Data / network cable between panels, 2C × 1.5 mm² fire rated | C31: 2C×1.5 mm² FR | D31: In 25 mm Ø PVC conduit | E31: Mtr | F31: TBA | G31: — | H31: TBA | K31: Only a riser stub shown — quantity to be taken from the riser / schematic.
A32: D.8 | B32: PVC conduit 25 mm Ø, embedded in slab / wall, with all fittings | C32: 25 mm Ø PVC | D32: Concealed | E32: Mtr | F32: 1169 | G32: ='Assumptions & Notes'!$B$10 -> 14 | H32: =ROUND(F32*G32*(1+'Assumptions & Notes'!$B$16),0) -> 18003 | J32: =IF(N(I32)=0,"",H32*I32) | K32: Sum of the three routed circuits; assumes one conduit per circuit route.
A33: D.9 | B33: G.I. back box 3"×3" for manual call point | C33: 3"×3" G.I. | D33: 1200 mm from FFL | E33: Nos | F33: 3 | G33: ='Assumptions & Notes'!$B$10 -> 14 | H33: =F33*G33 -> 42 | J33: =IF(N(I33)=0,"",H33*I33) | K33: Per legend mounting note.
A34: D.10 | B34: G.I. back box 2"×4" concealed, for fire telephone jack | C34: 2"×4" G.I. | D34: 1200 mm from FFL | E34: Nos | F34: 3 | G34: ='Assumptions & Notes'!$B$10 -> 14 | H34: =F34*G34 -> 42 | J34: =IF(N(I34)=0,"",H34*I34) | K34: Per legend mounting note.
A35: D.11 | B35: Conduit sleeve / slab opening for vertical riser penetration | C35: — | D35: — | E35: Nos | F35: 3 | G35: ='Assumptions & Notes'!$B$10 -> 14 | H35: =F35*G35 -> 42 | J35: =IF(N(I35)=0,"",H35*I35) | K35: Riser penetrations shown on the typical floor.
B37: TOTAL — FIRE ALARM & VOICE EVACUATION (Level 02–10 & 12–16) | J37: =SUM(J6:J35) -> 0
A39: Legend: blue = counted / input value • green = floor multiplier from 'Assumptions & Notes' • black bold = calculated total • yellow = enter your rate
A40: Cable and conduit totals include the wastage allowance set on the 'Assumptions & Notes' sheet.

Sheet Assumptions & Notes
A1: FIRE ALARM BOQ — BASIS OF QUANTITIES
A2: Drawing | B2: ICC-DLRC-SIG2-SD-MEP/FA-109 | C2: Title block, layout 'OVERALL'
A3: Title | B3: LEVEL-02 TO 10 & 12 TO 16 FLOOR FIRE ALARM & VOICE EVACUATION SYSTEM LAYOUT
A4: Revision / Date | B4: 01 — 15.09.2026 — REVISED AS PER COMMENTS | C4: Rev 00 issued for approval 31-07-2026
A5: Scale | B5: 1:200 | C5: Model space units = millimetres
A6: Drawn / Checked | B6: RAMADAN / ASIF
A7: System | B7: EST4 addressable, Edwards/EST SIGA-series devices + voice evacuation | C7: From drawing legend
A9: INPUT CELLS (blue = edit these; all BOQ totals recalculate)
A10: Typical floors covered by this drawing | B10: 14 | C10: L2–L10 (9 floors) + L12–L16 (5 floors). Excludes L11.
A11: Floors with 'CR ONLY IN LEVEL 02,04,06,08,10,12,14,16' | B11: 8 | C11: Drawing note beside 2 nos control relay modules.
A12: Floors with 'SD LOCATED ONLY IN LEVEL-6 & 12' | B12: 2 | C12: Drawing note beside 4 nos smoke detectors.
A13: Floors with 'AMPLIFIERS LOCATED ONLY IN LEVEL-03/09/15' | B13: 3 | C13: Drawing note beside amplifier symbol.
A14: Floors with 'SUB FACP LOCATED AT L10 ONLY' | B14: 1 | C14: Drawing note beside SFACP symbol.
A15: Floors with 'BOOSTER POWER SUPPLY ONLY IN LEVEL-09' | B15: 1 | C15: Drawing note beside BPS symbol.
A16: Wastage / site-routing allowance on cable & conduit | B16: 0.1 | C16: Applied to cable and conduit totals only.
A18: HOW THE QUANTITIES WERE DERIVED
A19: Device quantities are a machine count of the symbol blocks placed on the typical-floor plan in the DXF model space (plan area X 1,182,957 to 1,248,207 / Y -103,142 to -66,592 in model space).
A20: Legend symbols and the installation-detail sketches on the same sheet were excluded from the count by coordinate zone, so nothing is double counted.
A21: Two independent cross-checks agree with the block count:
A22: • Detectors: 36 OS + 5 OSI + 31 LPS + 26 MS + 1 HI = 99. Device tags on the sheet read D16–D100 (85 on Loop 3) + D251–D260 (10 on Loop 4) = 95, plus the 4 detectors noted 'L6 & L12 only' which sit outside the tag sequence. 95 + 4 = 99. ✓
A23: • Modules: 6 CR + 3 break glass + 1 CT2 + 1 CC2 = 11 devices = 13 loop addresses (CT2 and CC2 are dual-input). Module tags read M132–M138 and M140–M145 = 13 addresses. ✓
A24: • Speakers: 13 ceiling speaker symbols vs speaker tags SP1–SP13 = 13. ✓
A25: Cable lengths are the true polyline length of each routing layer inside the plan area (FA-LOOP CABLE, FA-24V DC CIRCUIT, VE-SPEAKER CIRCUIT), converted mm → m. They are horizontal run only.
A26: Conduit is taken as the sum of the three circuit routes, per the legend note that every circuit runs inside 25mm Ø PVC conduit embedded in slab/wall.
A28: ITEMS TO VERIFY BEFORE PRICING — the drawing does not settle these
A29: Vertical drops not included | B29: Cable lengths are the plan (horizontal) run only. Add drops to device height, riser rises between floors, and panel terminations. Typical addition 15–25%.
A30: Fire telephone cable not routed | B30: The legend lists a fire telephone cable (2C×1.5mm² FR) and 3 telephone jacks are placed, but no routing polyline exists on the sheet. Quantity carried as 'to be advised'.
A31: Data / network cable not routed | B31: Only a 1 m riser stub is drawn on layer FA-DATA NETWORK CABLE. Inter-panel network cable must come from the riser diagram.
A32: No wall speakers, sounder-flashers or staircase speakers on this floor | B32: Blocks WS, SF, SF-WP, CF and WSF-WP exist in the legend but are placed zero times on the plan. Confirm staircase / lobby audibility is covered by another drawing, or the floor is short of coverage.
A33: Isolator count vs general note 4 | B33: Note 4 requires an isolator base every 15 detectors. This floor has 99 detectors and 6 isolator bases (5 OSI + 1 HI) = 1 per 16.5. Isolators are counted per loop across floors, so confirm against the loop schematic.
A34: Speaker circuit returns off-sheet | B34: Note reads 'SPEAKER CIRCUIT RETURN TO CC2A @ TEL RM'. Riser lengths are outside this drawing.
A35: 2 nos heat detector symbols outside the plan | B35: Two HD blocks sit at X ≈ -1,200,000 on layer E-670-M_FSP_FSA-1, far outside the floor plate — orphan content from another drawing. Excluded from the BOQ. Confirm they are not required.
A36: Fire dome, back boxes and terminations | B36: Carried per the legend's mounting notes. Confirm against the manufacturer's installation detail before ordering.

Sheet Device Schedule
A1: TYPICAL-FLOOR DEVICE SCHEDULE — as placed on drawing ICC-DLRC-SIG2-SD-MEP/FA-109 Rev 01
A2: One row per symbol on the typical floor plan. The tag column is the nearest device label found in the drawing; blank where no label sits within 2.5 m.
A4: # | B4: Symbol | C4: Device / model | D4: Device tag on drawing | E4: X (mm) | F4: Y (mm) | G4: Tag distance (mm)
A5: 1 | B5: BPS | C5: Booster power supply (BPS10A/230) | D5: FACP01-GF/LP3/D17 | E5: 1192414 | F5: -98801 | G5: 714
A6: 2 | B6: CC2 | C6: Dual input riser module (SIGA-CC2A) | D6: FACP01-GF/LP3/D16 | E6: 1192469 | F6: -99713 | G6: 1280
A7: 3 | B7: CR | C7: Control relay module (SIGA-CR) | D7: AMP03-P3/CK4/SP8 | E7: 1200217 | F7: -88402 | G7: 1927
A8: 4 | B8: CR | C8: Control relay module (SIGA-CR) | E8: 1189517 | F8: -90227
A9: 5 | B9: CR | C9: Control relay module (SIGA-CR) | D9: AMP03-P3/CK4/SP5 | E9: 1227250 | F9: -94870 | G9: 1233
A10: 6 | B10: CR | C10: Control relay module (SIGA-CR) | D10: FACP01-GF/LP3/D32 | E10: 1218098 | F10: -96370 | G10: 976
A11: 7 | B11: CR | C11: Control relay module (SIGA-CR) | D11: FACP01-GF/LP3/D23 | E11: 1203394 | F11: -96370 | G11: 1568
A12: 8 | B12: CR | C12: Control relay module (SIGA-CR) | D12: FACP01-GF/LP3/D37 | E12: 1225015 | F12: -96370 | G12: 1404
A13: 9 | B13: CS | C13: Ceiling speaker (EST-S186C) | D13: FACP01-GF/LP3/D99 | E13: 1190157 | F13: -70794 | G13: 1510
A14: 10 | B14: CS | C14: Ceiling speaker (EST-S186C) | D14: AMP03-P3/CK4/SP12 | E14: 1190157 | F14: -78771 | G14: 1516
A15: 11 | B15: CS | C15: Ceiling speaker (EST-S186C) | D15: FACP01-GF/LP3/D73 | E15: 1201396 | F15: -85986 | G15: 888
A16: 12 | B16: CS | C16: Ceiling speaker (EST-S186C) | D16: FACP01-GF/LP3/D87 | E16: 1190157 | F16: -86768 | G16: 774
A17: 13 | B17: CS | C17: Ceiling speaker (EST-S186C) | D17: AMP03-P3/CK4/SP7 | E17: 1201352 | F17: -91601 | G17: 478
A18: 14 | B18: CS | C18: Ceiling speaker (EST-S186C) | D18: AMP03-P3/CK4/SP9 | E18: 1192744 | F18: -92279 | G18: 787
A19: 15 | B19: CS | C19: Ceiling speaker (EST-S186C) | D19: FACP01-GF/LP3/D82 | E19: 1190157 | F19: -94749 | G19: 793
A20: 16 | B20: CS | C20: Ceiling speaker (EST-S186C) | D20: AMP03-P3/CK4/SP6 | E20: 1236637 | F20: -95542 | G20: 419
... A96: 92 | B96: OS | C96: Smoke detector, standard base (SIGA-OSD-FCN + SIGA-SB) | D96: FACP01-GF/LP3/D87 | E96: 1190157 | F96: -86276 | G96: 291
A97: 93 | B97: OS | C97: Smoke detector, standard base (SIGA-OSD-FCN + SIGA-SB) | E97: 1205143 | F97: -86636
A98: 94 | B98: OS | C98: Smoke detector, standard base (SIGA-OSD-FCN + SIGA-SB) | D98: FACP01-GF/LP3/M140 | E98: 1197572 | F98: -86636 | G98: 1136
A99: 95 | B99: OS | C99: Smoke detector, standard base (SIGA-OSD-FCN + SIGA-SB) | D99: FACP01-GF/LP3/M140 | E99: 1196156 | F99: -88114 | G99: 1995
A100: 96 | B100: OS | C100: Smoke detector, standard base (SIGA-OSD-FCN + SIGA-SB) | D100: FACP01-GF/LP3/D70 | E100: 1210857 | F100: -89192 | G100: 1732
A101: 97 | B101: OS | C101: Smoke detector, standard base (SIGA-OSD-FCN + SIGA-SB) | E101: 1222057 | F101: -89391
A102: 98 | B102: OS | C102: Smoke detector, standard base (SIGA-OSD-FCN + SIGA-SB) | D102: FACP01-GF/LP3/D74 | E102: 1201357 | F102: -91112 | G102: 240
A103: 99 | B103: OS | C103: Smoke detector, standard base (SIGA-OSD-FCN + SIGA-SB) | D103: FACP01-GF/LP3/D75 | E103: 1192735 | F103: -91794 | G103: 906
A104: 100 | B104: OS | C104: Smoke detector, standard base (SIGA-OSD-FCN + SIGA-SB) | E104: 1197572 | F104: -91960
A105: 101 | B105: OS | C105: Smoke detector, standard base (SIGA-OSD-FCN + SIGA-SB) | E105: 1205143 | F105: -91999
A106: 102 | B106: OS | C106: Smoke detector, standard base (SIGA-OSD-FCN + SIGA-SB) | D106: FACP01-GF/LP3/D53 | E106: 1244989 | F106: -92353 | G106: 2179
A107: 103 | B107: OS | C107: Smoke detector, standard base (SIGA-OSD-FCN + SIGA-SB) | D107: FACP01-GF/LP3/D72 | E107: 1206857 | F107: -93692 | G107: 250
A108: 104 | B108: OS | C108: Smoke detector, standard base (SIGA-OSD-FCN + SIGA-SB) | D108: FACP01-GF/LP3/D82 | E108: 1190157 | F108: -94276 | G108: 384
A109: 105 | B109: OS | C109: Smoke detector, standard base (SIGA-OSD-FCN + SIGA-SB) | D109: AMP03-P3/CK4/SP6 | E109: 1236157 | F109: -95542 | G109: 798
A110: 106 | B110: OS | C110: Smoke detector, standard base (SIGA-OSD-FCN + SIGA-SB) | D110: AMP03-P3/CK4/SP5 | E110: 1228157 | F110: -95542 | G110: 398
A111: 107 | B111: OS | C111: Smoke detector, standard base (SIGA-OSD-FCN + SIGA-SB) | D111: AMP03-P3/CK4/SP4 | E111: 1220157 | F111: -95542 | G111: 873
A112: 108 | B112: OS | C112: Smoke detector, standard base (SIGA-OSD-FCN + SIGA-SB) | D112: AMP03-P3/CK4/SP2 | E112: 1204157 | F112: -95542 | G112: 750
A113: 109 | B113: OS | C113: Smoke detector, standard base (SIGA-OSD-FCN + SIGA-SB) | D113: AMP03-P3/CK4/SP1 | E113: 1196157 | F113: -95542 | G113: 746
A114: 110 | B114: OS | C114: Smoke detector, standard base (SIGA-OSD-FCN + SIGA-SB) | D114: FACP01-GF/LP3/D17 | E114: 1193457 | F114: -97517 | G114: 941
A115: 111 | B115: OS | C115: Smoke detector, standard base (SIGA-OSD-FCN + SIGA-SB) | D115: FACP01-GF/LP3/D41 | E115: 1230132 | F115: -97542 | G115: 1540
A116: 112 | B116: OS | C116: Smoke detector, standard base (SIGA-OSD-FCN + SIGA-SB) | D116: FACP01-GF/LP3/D46 | E116: 1243605 | F116: -98695 | G116: 933
...
